from fastapi import APIRouter, HTTPException
from app.db.models.users import User

router = APIRouter()

# Create a new user
@router.post("/users")
async def create_user(user: User):
    try:
        # Logic to save the user to the database
        return {"message": "User created successfully", "user": user}
    except Exception as e:
        raise HTTPException(status_code=400, detail=str(e))

# Get user by ID
@router.get("/users/{user_id}")
async def get_user(user_id: str):
    try:
        # Logic to fetch user from the database
        return {"user_id": user_id, "details": "User details fetched"}
    except Exception as e:
        raise HTTPException(status_code=404, detail=str(e))

# Update user details
@router.put("/users/{user_id}")
async def update_user(user_id: str, user: User):
    try:
        # Logic to update user in the database
        return {"message": "User updated successfully", "user": user}
    except Exception as e:
        raise HTTPException(status_code=400, detail=str(e))

# Delete a user
@router.delete("/users/{user_id}")
async def delete_user(user_id: str):
    try:
        # Logic to delete the user from the database
        return {"message": "User deleted successfully"}
    except Exception as e:
        raise HTTPException(status_code=400, detail=str(e))
